Workbook
Name Display_Week: ProjectSchedule!$E$4
Name Project_Start: ProjectSchedule!$E$3
Name task_end: ProjectSchedule!$G1
Name task_progress: ProjectSchedule!$D1
Name task_schedule: ProjectSchedule!$F1
Name task_start: ProjectSchedule!$E1
Name today: TODAY()

Sheet ProjectSchedule
A1: Create a Project Schedule in this worksheet. Enter title of this project in cell B1. Information about how to use this worksheet, including instructions for screen readers and the author of this workbook is in the About worksheet. Continue navigating down column A to hear further instructions. | B1: KẾ HOẠCH TRIỂN KHAI MỞ GIAO THỨC SMB2
A2: Enter Company Name in cell B2.
A3: Enter the name of the Project Lead in cell B3. Enter the Project Start date in cell E3. Pooject Start: label is in cell C3. | C3: Project Start: | E3: 46024
A4: The Display Week in cell E4 represents the starting week to display in the project schedule in cell I4. The project start date is considered Week 1. To change the display week, simply enter a new week number in cell E4. The starting date for each week, starting with the display week from cell E4, starts in cell I4 and is auto calculated. There are 8 weeks represented in this view from cell I4 through cell BF4. You should not modify these cells. Display Week: label is in cell C4. | C4: Display Week: | E4: 1 | J4: =J5 -> 46020
A5: Cells I5 through BL5 contain the day number for the week represented in the cell block above each date cell and are auto calculated. You should not modify these cells. Today's date is outlined in Red (hex #AD3815) from today's date in row 5 through the entire date column to the end of the project schedule. | J5: =Project_Start-WEEKDAY(Project_Start,1)+2+7*(Display_Week-1) -> 46020 | K5: =J5+1 -> 46021 | L5: =K5+1 -> 46022 | M5: =L5+1 -> 46023 | N5: =M5+1 -> 46024 | O5: =N5+1 -> 46025 | P5: =O5+1 -> 46026 | Q5: =P5+1 -> 46027 | R5: =Q5+1 -> 46028 | ... BC5: =BB5+1 -> 46065
A6: STT 序號 | B6: Nội dung công việc 工作內容 | C6: Trách nhiệm 擔當 | D6: Tiến độ hoàn thành 完成進度 | E6: Ngày dự kiến bắt đầu 預計開始時間 | F6: Ngày dự kiến hoàn thành 預計完成時間 | G6: Ngày hoàn thành thực tế 實際完成時間 | H6: Số lượng PC dự kiến 預計的 PC 數量 | I6: DAYS | J6: =LEFT(TEXT(J5,"ddd"),3) -> T2 | K6: =LEFT(TEXT(K5,"ddd"),3) -> T3 | L6: =LEFT(TEXT(L5,"ddd"),3) -> T4 | M6: =LEFT(TEXT(M5,"ddd"),3) -> T5 | N6: =LEFT(TEXT(N5,"ddd"),3) -> T6 | O6: =LEFT(TEXT(O5,"ddd"),3) -> T7 | P6: =LEFT(TEXT(P5,"ddd"),3) -> CN | Q6: =LEFT(TEXT(Q5,"ddd"),3) -> T2 | ... BC6: =LEFT(TEXT(BC5,"ddd"),3) -> T5
A7: 1 | B7: Xây dựng kế hoạch và phân bổ nhân lực thực hiện 制定計劃並安排人力 | C7: #01959 | D7: 1 | E7: 46024 | F7: 46025 | I7: =IF(OR(ISBLANK(task_start),ISBLANK(task_end)),"",task_end-task_start+1)
A8: 2 | B8: Mở giao thức SMB2 tại Xưởng 6 | C8: MIS | D8: =COUNTIFS(Total!J:J, "Đã hoàn thành 已完成", Total!B:B, "X6")/H8 -> 1 | E8: 46027 | F8: 46032 | H8: =COUNTIF(Total!B:B, "X6") -> 65 | I8: =IF(OR(ISBLANK(task_start),ISBLANK(task_end)),"",task_end-task_start+1)
A9: 3 | B9: Mở giao thức SMB2 tại Xưởng 1 | C9: MIS | D9: =COUNTIFS(Total!J:J, "Đã hoàn thành 已完成", Total!B:B, "X1")/H9 -> 1 | E9: 46027 | F9: 46032 | H9: =COUNTIF(Total!B:B, "X1") -> 126 | I9: =IF(OR(ISBLANK(task_start),ISBLANK(task_end)),"",task_end-task_start+1)
A10: 4 | B10: Mở giao thức SMB2 tại Xưởng 3 | C10: MIS | D10: =COUNTIFS(Total!J:J,"Đã hoàn thành 已完成",Total!B:B,"X3")/H10 -> 1 | E10: 46034 | F10: 46038 | H10: =COUNTIF(Total!B:B, "X3") -> 248
A11: 5 | B11: Mở giao thức SMB2 tại Xưởng 4 | C11: MIS | D11: =COUNTIFS(Total!J:J,"Đã hoàn thành 已完成",Total!B:B,"X4")/H11 -> 1 | E11: 46041 | F11: 46046 | H11: =COUNTIF(Total!B:B,"X4") -> 181
A12: 6 | B12: Mở giao thức SMB2 tại Xưởng 5 | C12: MIS | D12: =COUNTIFS(Total!J:J,"Đã hoàn thành 已完成",Total!B:B,"X5")/H12 -> 1 | E12: 46048 | F12: 46052 | H12: =COUNTIF(Total!B:B,"X5") -> 52 | I12: =IF(OR(ISBLANK(task_start),ISBLANK(task_end)),"",task_end-task_start+1)
A13: 5 | B13: Mở giao thức SMB2 tại Xưởng 2 | C13: MIS | D13: =COUNTIFS(Total!J:J,"Đã hoàn thành 已完成",Total!B:B,"X2")/H13 -> 1 | E13: 46055 | F13: 46060 | H13: =COUNTIF(Total!B:B,"X2") -> 126
A14: 6 | B14: Mở giao thức SMB2 Máy tính manage | C14: MIS | D14: =COUNTIFS(Total!J:J,"Đã hoàn thành 已完成",Total!B:B,"Manager")/H14 -> 1 | E14: 46060 | F14: 46060 | H14: =COUNTIF(Total!B:B, "Manager") -> 33 | I14: =IF(OR(ISBLANK(task_start),ISBLANK(task_end)),"",task_end-task_start+1)
A15: 8 | B15: Tổng hợp báo cáo 彙總報告 | C15: MIS | E15: 46062 | F15: 46065 | I15: =IF(OR(ISBLANK(task_start),ISBLANK(task_end)),"",task_end-task_start+1)
A16: This row marks the end of the Project Schedule. DO NOT enter anything in this row. Insert new rows ABOVE this one to continue building out your Project Schedule. | B16: Insert new rows ABOVE this one | I16: =IF(OR(ISBLANK(task_start),ISBLANK(task_end)),"",task_end-task_start+1)
Q18: Kế hoạch dự kiến 預計計劃 | V18: Tiến độ thực tế 實際進度

Sheet Sheet1
A3: Row Labels | B3: Count of Khóa SMB1
A4: P | B4: 827
A5: X | B5: 4
A6: Grand Total | B6: 831
A12: Row Labels | B12: Count of Mở SMB2
A13: P | B13: 820
A14: X | B14: 11
A15: Grand Total | B15: 831

Sheet Total
A1: STT 序號 | B1: Xưởng 廠別 | C1: Bộ phận 部門 | D1: PC-NAME | E1: IP | F1: Window | G1: USER | H1: Khóa SMB1 | I1: Mở SMB2 | J1: Tiến độ 進度 | K1: Ngày thực hiện 執行日期 | L1: Người thực hiện 執行者 | M1: Ghi chú 備註
A2: 1 | B2: Manager | C2: Tài Vụ 財務 | D2: JAMES | E2: DHCP | F2: 11 Pro | G2: DL01 | H2: P | I2: P | J2: Đã hoàn thành 已完成 | K2: 46032 | L2: #15060
A3: 2 | B3: Manager | C3: KAIFA | D3: LIAO-KAIFA | E3: DHCP | F3: 11 Pro | G3: DL06 | H3: P | I3: P | J3: Đã hoàn thành 已完成 | K3: 46032 | L3: #17655
A4: 3 | B4: Manager | C4: DAP4 四廠沖壓 | D4: CHANG | E4: DHCP | F4: 11 Pro | G4: DL13 | H4: P | I4: P | J4: Đã hoàn thành 已完成 | K4: 46032 | L4: #17655
A5: 4 | B5: Manager | C5: DAP4 四廠沖壓 | D5: DAP4-CHANG | E5: DHCP | F5: 11 Pro | G5: DL13 | H5: P | I5: P | J5: Đã hoàn thành 已完成 | K5: 46032 | L5: #17655
A6: 5 | B6: Manager | C6: DAP4 四廠沖壓 | D6: CHANG | E6: DHCP | F6: 11 Pro | G6: DL13 | H6: P | I6: P | J6: Đã hoàn thành 已完成 | K6: 46032 | L6: #17655
A7: 6 | B7: Manager | C7: VPTGD 總經理室 | D7: ANDY | E7: DHCP | F7: 11 Pro | G7: DL19 | H7: P | I7: P | J7: Đã hoàn thành 已完成 | K7: 46032 | L7: #17655
A8: 7 | B8: Manager | C8: THUMUA 採購 | D8: ROBERT-PC | E8: DHCP | F8: 11 Pro | G8: DL57 | H8: P | I8: P | J8: Đã hoàn thành 已完成 | K8: 46032 | L8: #17655
A9: 8 | B9: Manager | C9: VPTGD 總經理室 | D9: MING | E9: DHCP | F9: 11 Pro | G9: DL70 | H9: P | I9: P | J9: Đã hoàn thành 已完成 | K9: 46032 | L9: #17655
A10: 9 | B10: Manager | C10: VPTGD 總經理室 | D10: MR.ArthurWang | E10: DHCP | F10: 11 Pro | G10: DL76 | H10: P | I10: P | J10: Đã hoàn thành 已完成 | K10: 46032 | L10: #17655
A11: 10 | B11: Manager | C11: VPTGD 總經理室 | D11: ARTHUR_WANG | E11: DHCP | F11: 11 Pro | G11: DL76 | H11: P | I11: P | J11: Đã hoàn thành 已完成 | K11: 46032 | L11: #18499
A12: 11 | B12: Manager | C12: KINHDOANH 業務 | D12: GLEN | E12: DHCP | F12: 11 Pro | G12: DL77 | H12: P | I12: P | J12: Đã hoàn thành 已完成 | K12: 46032 | L12: #20021
A13: 12 | B13: Manager | C13: KTSX 生技 | D13: Mr-JACKIELIN | E13: DHCP | F13: 11 Pro | G13: DL133 | H13: P | I13: P | J13: Đã hoàn thành 已完成 | K13: 46032 | L13: #20021
... A171: 170 | B171: X3 | C171: KHO LK3 三廠零件倉庫 | D171: LK305 | E171: 192.168.32.61 | F171: 11 Pro | G171: #24123 | H171: P | I171: P | J171: Đã hoàn thành 已完成 | K171: 46032 | L171: #20021
A172: 171 | B172: X3 | C172: DAP3 三廠沖壓 | D172: CNC-3D | E172: 192.168.32.200 | F172: 7 Pro | G172: #07286 | H172: X | I172: P | J172: Đã hoàn thành 已完成 | K172: 46032 | L172: #20021 | M172: - Máy CNC kết nốt máy tính lấy dữ liệu bằng giao thức SMB1
A173: 172 | B173: X3 | C173: DAP3 三廠沖壓 | D173: CNC-LASER- PC | E173: DHCP | F173: 10 Pro | G173: #00868 | H173: P | I173: P | J173: Đã hoàn thành 已完成 | K173: 46032 | L173: #20021
A174: 173 | B174: X3 | C174: DAP3 三廠沖壓 | D174: DAP301 | E174: 192.168.32.21 | F174: 11 Pro | G174: #03229 | H174: P | I174: P | J174: Đã hoàn thành 已完成 | K174: 46032 | L174: #20021
A175: 174 | B175: X3 | C175: DAP3 三廠沖壓 | D175: DAP302 | E175: 192.168.32.64 | F175: 11 Pro | G175: #02260 | H175: P | I175: P | J175: Đã hoàn thành 已完成 | K175: 46032 | L175: #20021
A176: 175 | B176: X3 | C176: DAP3 三廠沖壓 | D176: DAP303 | E176: 192.168.32.23 | F176: 11 Pro | G176: #10368 | H176: P | I176: P | J176: Đã hoàn thành 已完成 | K176: 46032 | L176: #20021
A177: 176 | B177: X3 | C177: DAP3 三廠沖壓 | D177: DAP304 | E177: 192.168.32.24 | F177: 11 Pro | G177: #01283 | H177: P | I177: P | J177: Đã hoàn thành 已完成 | K177: 46032 | L177: #20021
A178: 177 | B178: X3 | C178: DAP3 三廠沖壓 | D178: DAP305 | E178: 192.168.32.25 | F178: 11 Pro | G178: #00172 | H178: P | I178: P | J178: Đã hoàn thành 已完成 | K178: 46032 | L178: #20021
A179: 178 | B179: X3 | C179: DAP3 三廠沖壓 | D179: DAP306 | E179: 192.168.32.26 | F179: 11 Pro | G179: #10367 | H179: P | I179: P | J179: Đã hoàn thành 已完成 | K179: 46032 | L179: #20021
A180: 179 | B180: X3 | C180: DAP3 三廠沖壓 | D180: DAP307 | E180: 192.168.32.27 | F180: 11 Pro | G180: #26001 | H180: P | I180: P | J180: Đã hoàn thành 已完成 | K180: 46032 | L180: #20021
A181: 180 | B181: X3 | C181: DAP3 三廠沖壓 | D181: DAP308 | E181: 192.168.32.67/10.10.10.2 | F181: 11 Pro | G181: #23205 | H181: P | I181: P | J181: Đã hoàn thành 已完成 | K181: 46032 | L181: #20021
A182: 181 | B182: X3 | C182: DAP3 三廠沖壓 | D182: DAP309 | E182: 192.168.32.70 | F182: 11 Pro | G182: #19230 | H182: P | I182: P | J182: Đã hoàn thành 已完成 | K182: 46032 | L182: #20021
A183: 182 | B183: X3 | C183: DAP3 三廠沖壓 | D183: DAP310 | E183: 192.168.32.71 | F183: 11 Pro | G183: #08917 | H183: P | I183: P | J183: Đã hoàn thành 已完成 | K183: 46032 | L183: #20021
A184: 183 | B184: X3 | C184: DAP3 三廠沖壓 | D184: DAP311 | E184: 192.168.32.72 | F184: 11 Pro | G184: #02857 | H184: P | I184: P | J184: Đã hoàn thành 已完成 | K184: 46032 | L184: #20021
... A479: 478 | B479: X4 | C479: KAIFA | D479: KF-VN26040 | E479: DHCP | F479: 11 Pro | G479: #26040 | H479: P | I479: P | J479: Đã hoàn thành 已完成 | K479: 46032 | L479: #17655
A480: 479 | B480: X4 | C480: KM 模具 | D480: CNC | E480: 192.192.200.2 | F480: XP | G480: #15374 | H480: X | I480: X | J480: Đã hoàn thành 已完成 | K480: 46032 | L480: #15060 | M480: - Máy CNC kết nốt máy tính lấy dữ liệu bằng giao thức SMB1
A481: 480 | B481: X4 | C481: KM 模具 | D481: CNC11 | E481: 192.168.33.160/192.192.200.131 | F481: 11 Pro | G481: #11706 | H481: P | I481: P | J481: Đã hoàn thành 已完成 | K481: 46032 | L481: #15060
A482: 481 | B482: X4 | C482: KM 模具 | D482: CNC12 | E482: 192.192.200.132 | F482: 10 Pro | G482: #08904 | H482: P | I482: P | J482: Đã hoàn thành 已完成 | K482: 46032 | L482: #15060
A483: 482 | B483: X4 | C483: KM 模具 | D483: CNC13 | E483: 192.168.33.162 | F483: 11 Pro | G483: #01705 | H483: P | I483: P | J483: Đã hoàn thành 已完成 | K483: 46032 | L483: #15060
A484: 483 | B484: X4 | C484: KM 模具 | D484: CNC14 | E484: 192.168.33.163/192.168.200.3 | F484: 10 Pro | G484: #10567 | H484: P | I484: P | J484: Đã hoàn thành 已完成 | K484: 46032 | L484: #15060
A485: 484 | B485: X4 | C485: KM 模具 | D485: CNC4 | E485: 192.192.200.4 | F485: 10 Pro | G485: #03412 | H485: P | I485: P | J485: Đã hoàn thành 已完成 | K485: 46032 | L485: #15060
A486: 485 | B486: X4 | C486: KM 模具 | D486: KM01 | E486: 192.168.33.121 | F486: 11 Pro | G486: #07702 | H486: P | I486: P | J486: Đã hoàn thành 已完成 | K486: 46032 | L486: #15060
A487: 486 | B487: X4 | C487: KM 模具 | D487: KM02 | E487: 192.168.33.122 | F487: 11 Pro | G487: #07153 | H487: P | I487: P | J487: Đã hoàn thành 已完成 | K487: 46032 | L487: #15060
A488: 487 | B488: X4 | C488: KM 模具 | D488: KM03 | E488: 192.168.33.123 | F488: 11 Pro | G488: #01465 | H488: P | I488: P | J488: Đã hoàn thành 已完成 | K488: 46032 | L488: #15060
A489: 488 | B489: X4 | C489: KM 模具 | D489: KM04 | E489: 192.168.33.124/192.192.200.1 | F489: 11 Pro | G489: #10406 | H489: P | I489: P | J489: Đã hoàn thành 已完成 | K489: 46032 | L489: #15060
A490: 489 | B490: X4 | C490: KM 模具 | D490: KM05 | E490: 192.168.33.125 | F490: 11 Pro | G490: #16198 | H490: P | I490: P | J490: Đã hoàn thành 已完成 | K490: 46032 | L490: #15060
A491: 490 | B491: X4 | C491: KM 模具 | D491: KM06 | E491: 192.168.33.126 | F491: 11 Pro | G491: #03048 | H491: P | I491: P | J491: Đã hoàn thành 已完成 | K491: 46032 | L491: #15060
...
