Workbook
Name Display_Week: Plan!$E$4
Name Display_Week: #REF!
Name Project_Start: Plan!$E$3
Name Project_Start: #REF!
Name task_end: Plan!$G1
Name task_progress: Plan!$D1
Name task_schedule: Plan!$F1
Name task_start: Plan!$E1
Name today: TODAY()

Sheet Difficult
A1: Khó khăn: Log theo dõi sử dụng máy photocopy không có đầy đủ thông tin phục vụ tổng hợp theo dõi sử dụng máy hàng tháng | C1: Phương án: Thiết lập tài khoản sử dụng trên máy photocopy theo tên máy tính sử dụng. Cài đặt tài khoản đã thiết lập trên máy tính sử dụng
A2: LOG DỮ LIỆU XUẤT RA | C2: LOG DỮ LIỆU XUẤT RA
C28: CÀI ĐẶT TRÊN MÁY TÍNH

Sheet Plan
A1: KẾ HOẠCH THIẾT LẬP, CÀI ĐẶT TÀI KHOẢN SỬ DỤNG MÁY PHOTOCOPY XEROX ALTALINK C8155
A3: Enter the name of the Project Lead in cell B3. Enter the Project Start date in cell E3. Pooject Start: label is in cell C3. | C3: Ngày bắt đầu | E3: 46023
A4: The Display Week in cell E4 represents the starting week to display in the project schedule in cell I4. The project start date is considered Week 1. To change the display week, simply enter a new week number in cell E4. The starting date for each week, starting with the display week from cell E4, starts in cell I4 and is auto calculated. There are 8 weeks represented in this view from cell I4 through cell BF4. You should not modify these cells. Display Week: label is in cell C4. | C4: Tuần | E4: 1 | J4: =S5 -> 46029
A5: Cells I5 through BL5 contain the day number for the week represented in the cell block above each date cell and are auto calculated. You should not modify these cells. Today's date is outlined in Red (hex #AD3815) from today's date in row 5 through the entire date column to the end of the project schedule. | J5: =Project_Start-WEEKDAY(Project_Start,1)+2+7*(Display_Week-1) -> 46020 | K5: =J5+1 -> 46021 | L5: =K5+1 -> 46022 | M5: =L5+1 -> 46023 | N5: =M5+1 -> 46024 | O5: =N5+1 -> 46025 | P5: =O5+1 -> 46026 | Q5: =P5+1 -> 46027 | R5: =Q5+1 -> 46028 | ... AK5: =AJ5+1 -> 46047
A6: STT 序號 | B6: Nội dung công việc 工作內容 | C6: Trách nhiệm 擔當 | D6: Tiến độ hoàn thành 完成進度 | E6: Ngày dự kiến bắt đầu 預計開始時間 | F6: Ngày dự kiến hoàn thành 預計完成時間 | G6: Ngày hoàn thành thực tế 實際完成時間 | H6: Số lượng PC dự kiến 預計的 PC 數量 | I6: DAYS | J6: =LEFT(TEXT(J5,"ddd"),3) -> Mon | K6: =LEFT(TEXT(K5,"ddd"),3) -> Tue | L6: =LEFT(TEXT(L5,"ddd"),3) -> Wed | M6: =LEFT(TEXT(M5,"ddd"),3) -> Thu | N6: =LEFT(TEXT(N5,"ddd"),3) -> Fri | O6: =LEFT(TEXT(O5,"ddd"),3) -> Sat | P6: =LEFT(TEXT(P5,"ddd"),3) -> Sun | Q6: =LEFT(TEXT(Q5,"ddd"),3) -> Mon | ... AK6: =LEFT(TEXT(AK5,"ddd"),3) -> Sun
A7: 1 | B7: Xây dựng kế hoạch | C7: #18499 | D7: 1 | E7: 46024 | F7: 46025 | G7: 46032 | I7: =IF(OR(ISBLANK(task_start),ISBLANK(task_end)),"",task_end-task_start+1) -> 9
A8: 2 | B8: Tổng hợp danh sách và thiết lập tài khoản sử dụng trên các máy photocopy (8 máy) | C8: #18499 | D8: =COUNTA(Total!H2:H525)/524 -> 1 | E8: 46027 | F8: 46052 | H8: 524
A9: 3 | B9: Cài đặt trên các máy tính sử dụng máy photocopy tại phòng QLSX | C9: MIS | D9: =COUNTA(Total!I2:I50)/50 -> 0 | E9: 46055 | F9: 46066 | H9: =Total!A50 -> 49
A10: 4 | B10: Cài đặt trên các máy tính sử dụng máy photocopy tại phòng QA | C10: MIS | D10: =COUNTA(Total!I451:I476)/26 -> 0 | E10: 46055 | F10: 46066 | H10: =Total!A476 -> 26
A11: 5 | B11: Cài đặt trên các máy tính sử dụng máy photocopy tại phòng Kinh doanh | C11: MIS | D11: =COUNTA(Total!I51:I118)/68 -> 0 | E11: 46077 | F11: 46094 | H11: =Total!A118 -> 68
A12: 6 | B12: Cài đặt trên các máy tính sử dụng máy photocopy tại phòng Thu mua | C12: MIS | D12: =COUNTA(Total!I119:I183)/65 -> 0 | E12: 46077 | F12: 46094 | H12: =Total!A183 -> 65
A13: 7 | B13: Cài đặt trên các máy tính sử dụng máy photocopy tại phòng VPX3 | C13: MIS | D13: =COUNTA(Total!I279:I340)/62 -> 0 | E13: 46077 | F13: 46094 | H13: =Total!A340 -> 62
A14: 8 | B14: Cài đặt trên các máy tính sử dụng máy photocopy tại phòng Kaifa | C14: MIS | D14: =COUNTA(Total!I341:I450)/110 -> 0 | E14: 46097 | F14: 46116 | H14: =Total!A450 -> 110
A15: 9 | B15: Cài đặt trên các máy tính sử dụng máy photocopy tại phòng Gia công | C15: MIS | D15: =COUNTA(Total!I184:I278)/95 -> 0 | E15: 46118 | F15: 46136 | H15: =Total!A278 -> 95
A16: 10 | B16: Cài đặt trên các máy tính sử dụng máy photocopy tại phòng Dập 5 | C16: MIS | D16: =COUNTA(Total!I477:I525)/49 -> 0 | E16: 46118 | F16: 46136 | H16: =Total!A525 -> 49
N18: Kế hoạch dự kiến 預計計劃 | V18: Tiến độ thực tế 實際進度 | AD18: Ngày nghỉ 休假日

Sheet Total
A1: STT 序號 | B1: Vị trí đặt máy | C1: Bộ phận 部門 | D1: PC-NAME | E1: IP | F1: USER | G1: Tài khoản | H1: Đã tạo tài khoản | I1: Đã cài đặt | J1: Ngày thực hiện 執行日期 | K1: Người thực hiện 執行者 | L1: Ghi chú 備註
A2: 1 | B2: Văn phòng QLSX xưởng 1 加工部辦公室 | C2: QLSX 生管 | D2: MR-TONYLIN | E2: DHCP | F2: DL122 | G2: MR-TONYLIN | H2: P | K2: #15060
A3: 2 | C3: QLSX X1 一廠生管 | D3: BOTQLSX | E3: 192.168.31.60 | F3: #08886 | G3: BOTQLSX | H3: P | K3: #15060
A4: 3 | C4: QLSX X1 一廠生管 | D4: QLSX-MEETING | E4: 192.168.31.98 | F4: QLSX-MEET | G4: QLSX-MEETING | H4: P | K4: #15060
A5: 4 | C5: QLSX X1 一廠生管 | D5: QLSX-VN00072 | E5: DHCP | F5: #00072 | G5: QLSX-VN00072 | H5: P | K5: #15060
A6: 5 | C6: QLSX X1 一廠生管 | D6: QLSX-VN00637 | E6: DHCP | F6: #00637 | G6: QLSX-VN00637 | H6: P | K6: #15060
A7: 6 | C7: QLSX X1 一廠生管 | D7: QLSX-VN02547 | E7: DHCP | F7: #02547 | G7: QLSX-VN02547 | H7: P | K7: #15060
A8: 7 | C8: QLSX X1 一廠生管 | D8: QLSX-VN08886 | E8: DHCP | F8: #08886 | G8: QLSX-VN08886 | H8: P | K8: #15060
A9: 8 | C9: QLSX X1 一廠生管 | D9: QLSX-VN25783 | E9: DHCP | F9: #25783 | G9: QLSX-VN25783 | H9: P | K9: #15060
A10: 9 | C10: QLSX X1 一廠生管 | D10: VPX101 | E10: 192.168.31.1 | F10: #10437 | G10: VPX101 | H10: P | K10: #15060
A11: 10 | C11: QLSX X1 一廠生管 | D11: VPX102 | E11: 192.168.31.2 | F11: #00328 | G11: VPX102 | H11: P | K11: #15060
A12: 11 | C12: QLSX X1 一廠生管 | D12: VPX103 | E12: 192.168.31.3 | F12: #00854 | G12: VPX103 | H12: P | K12: #15060
A13: 12 | C13: QLSX X1 一廠生管 | D13: VPX104 | E13: 192.168.31.4 | F13: #04202 | G13: VPX104 | H13: P | K13: #15060
A14: 13 | C14: QLSX X1 一廠生管 | D14: VPX105 | E14: 192.168.31.5 | F14: #07789 | G14: VPX105 | H14: P | K14: #15060
... A50: 49 | C50: KHO NL1 一廠原料倉庫 | D50: NL108 | E50: 192.168.31.58 | F50: #02183 | G50: NL108 | H50: P | K50: #15060
A51: 1 | B51: Văn phòng Kinh Doanh 業務部辦公室 | C51: KINHDOANH 業務 | D51: GLEN | E51: DHCP | F51: DL77 | G51: GLEN | H51: P | K51: #15060
A52: 2 | C52: KINHDOANH 業務 | D52: KD_ANNE | E52: DHCP | F52: #16629 | G52: KD_ANNE | H52: P | K52: #15060
A53: 3 | C53: KINHDOANH 業務 | D53: KD01 | E53: 192.168.30.1 | F53: #08954 | G53: KD01 | H53: P | K53: #15060
A54: 4 | C54: KINHDOANH 業務 | D54: KD02 | E54: 192.168.30.4 | F54: #00766 | G54: KD02 | H54: P | K54: #15060
A55: 5 | C55: KINHDOANH 業務 | D55: KD-16363 | E55: DHCP | F55: #16363 | G55: KD-16363 | H55: P | K55: #15060
A56: 6 | C56: KINHDOANH 業務 | D56: KD-DIEP | E56: DHCP | F56: #01014 | G56: KD-DIEP | H56: P | K56: #15060
A57: 7 | C57: KINHDOANH 業務 | D57: KD-DUNG10839 | E57: DHCP | F57: #10839 | G57: KD-DUNG10839 | H57: P | K57: #15060
A58: 8 | C58: KINHDOANH 業務 | D58: KD-DUYANH | E58: DHCP | F58: #11287 | G58: KD-DUYANH | H58: P | K58: #15060
A59: 9 | C59: KINHDOANH 業務 | D59: KD-DUYEN | E59: DHCP | F59: #23987 | G59: KD-DUYEN | H59: P | K59: #15060
A60: 10 | C60: KINHDOANH 業務 | D60: KD-EmmaDung | E60: DHCP | F60: #11581 | G60: KD-EmmaDung | H60: P | K60: #15060
A61: 11 | C61: KINHDOANH 業務 | D61: KD-HANG | E61: DHCP | F61: #11288 | G61: KD-HANG | H61: P | K61: #15060
A62: 12 | C62: KINHDOANH 業務 | D62: KD-HAU8787 | E62: DHCP | F62: #08787 | G62: KD-HAU8787 | H62: P | K62: #15060
A63: 13 | C63: KINHDOANH 業務 | D63: KD-HOAI | E63: DHCP | F63: #24870 | G63: KD-HOAI | H63: P | K63: #15060
... A118: 68 | C118: KSNB 稽核室 | D118: PHUNGTUANHUNG | E118: DHCP | F118: #00720 | G118: PHUNGTUANHUNG | H118: P | K118: #15060
A119: 1 | B119: Thu mua 採購 | C119: THUMUA 採購 | D119: ROBERT-PC | E119: DHCP | F119: DL57 | G119: ROBERT-PC | H119: P | K119: #17655
A120: 2 | C120: THUMUA 採購 | D120: Mr-Peng | E120: DHCP | F120: TQ53 | G120: Mr-Peng | H120: P | K120: #17655
A121: 3 | C121: THUMUA 採購 | D121: BINH-TM | E121: DHCP | F121: #01737 | G121: BINH-TM | H121: P | K121: #17655
A122: 4 | C122: THUMUA 採購 | D122: TM01 | E122: 192.168.34.51 | F122: #24337 | G122: TM01 | H122: P | K122: #17655
A123: 5 | C123: THUMUA 採購 | D123: TM02 | E123: 192.168.34.52 | F123: #10949 | G123: TM02 | H123: P | K123: #17655
A124: 6 | C124: THUMUA 採購 | D124: TM03 | E124: 192.168.34.53 | F124: #17064 | G124: TM03 | H124: P | K124: #17655
A125: 7 | C125: THUMUA 採購 | D125: TM04 | E125: 192.168.34.54 | F125: #26156 | G125: TM04 | H125: P | K125: #17655
A126: 8 | C126: THUMUA 採購 | D126: TM05 | E126: 192.168.34.55 | F126: #16743 | G126: TM05 | H126: P | K126: #17655
A127: 9 | C127: THUMUA 採購 | D127: TM06 | E127: 192.168.34.56 | F127: #18155 | G127: TM06 | H127: P | K127: #17655
A128: 10 | C128: THUMUA 採購 | D128: TM07 | E128: 192.168.34.57 | F128: #19343 | G128: TM07 | H128: P | K128: #17655
A129: 11 | C129: THUMUA 採購 | D129: TM08 | E129: 192.168.34.58 | F129: #01574 | G129: TM08 | H129: P | K129: #17655
...
