Workbook

Sheet PLAN (2)
A1: 步驟 月份 | D1: 2024.4 | H1: 2024.5 | M1: 2024.6 | Q1: 2024.7
D2: W14 | E2: W15 | F2: W16 | G2: W17 | H2: W18 | I2: W19 | J2: W20 | K2: W21 | L2: W22 | M2: W23 | N2: W24 | O2: W25 | P2: W26 | Q2: W27 | R2: W28 | S2: W29 | T2: W30 | U2: W31
A3: 環境設備 | B3: 1 | C3: 準備主機環境
B4: 2 | C4: 建立部門 Group，給各部門建立訪問 AD 帳號
A5: 應用對策 | B5: 1 | C5: 根據 ISO27001 標準進行對策檢驗、測驗
B6: 2 | C6: 檢驗並測試 Windows Server Update Services
B7: 3 | C7: 應用在 AD 上的管理對策：Password;Block Registry, Block Manager, Block USB, CD, Block AppZalo-Bittorrent, Install 7Zip…
A8: 導入應用連接到 AD | B8: 1 | C8: 給 6 廠電腦導入連接到 AD
B9: 2 | C9: 給 3 廠辦公室電腦導入連接到 AD
B10: 3 | C10: 給 1 廠電腦導入連接到 AD
B11: 4 | C11: 給 3 廠電腦導入連接到 AD
B12: 5 | C12: 給 2 廠電腦導入連接到 AD
B13: 6 | C13: 給 5 廠電腦導入連接到 AD
B14: 7 | C14: 給 4 廠電腦導入連接到 AD
B15: 8 | C15: 給開發部電腦導入連接到 AD
A16: 支援使用者 | B16: 1 | C16: 支援使用者處理發生問題 (若有)
A17: 更新 ISO27001 文件 | B17: 1 | C17: 彙總數據，總結導入 AD 計劃以及更新 ISO27001 文件
C18: Update: 2024/05/03 | E18: 已完成 | I18: 執行中 | N18: 未執行

Sheet Repost
B3: Values
A4: Dep | B4: Count of USER | C4: Count of Disable | D4: Count of Delete
A5: An toàn - Môi trường 安環室 | B5: 10 | C5: 3 | D5: 2
A6: Cán ống 製管事業部 | B6: 1
A7: Cắt 3 三 廠素材 | B7: 7 | C7: 2 | D7: 2
A8: Công Vụ 工務 | B8: 2
A9: Dập 1 一廠沖壓 | B9: 12 | C9: 3 | D9: 2
A10: Dập 3 三廠沖壓 | B10: 9 | C10: 1
A11: Dập 4 四廠沖壓 | B11: 17 | C11: 3 | D11: 3
A12: Dập 5 五廠沖壓 | B12: 15 | C12: 1 | D12: 1
A13: Dập 6 六廠沖壓 | B13: 15 | C13: 3 | D13: 2
A14: Đúc 壓鑄部 | B14: 17 | C14: 4 | D14: 2
A15: GDO 總經理室 | B15: 8 | C15: 1 | D15: 1
A16: Gia công 加工部 | B16: 18 | C16: 3 | D16: 3
A17: Hàn 1 一廠焊接 | B17: 14
A18: Hàn 3 三廠焊接 | B18: 14 | C18: 2 | D18: 2
A19: Hàn 6 六廠焊接 | B19: 12 | C19: 2 | D19: 1
A20: IS | B20: 3
A21: Kaifa 開發課 | B21: 117 | C21: 10 | D21: 8
A22: KHO LK1 一廠零件庫 | B22: 5 | C22: 1 | D22: 1
A23: KHO LK3 三廠零件庫 | B23: 5
A24: KHO NL1 一廠原料庫 | B24: 5
A25: Khuôn mẫu 模具課 | B25: 20 | C25: 1 | D25: 1
A26: Kinh doanh 業務部 | B26: 49 | C26: 4 | D26: 3
A27: KSNB 稽核室 | B27: 5 | C27: 2
A28: KTSX 生技 | B28: 9 | C28: 3 | D28: 3
A29: Lắp ráp 6 六廠組裝 | B29: 7
A30: Lắp ráp 組裝 | B30: 5 | C30: 1
A31: MIS | B31: 19 | C31: 2 | D31: 2
A32: Nhân sự-tổng vụ 人事-總務 | B32: 21 | C32: 1 | D32: 1
A33: QA | B33: 21 | C33: 2 | D33: 2
A34: QC 1 一廠品管 | B34: 28 | C34: 2 | D34: 1
A35: QC 2 二廠品管 | B35: 5 | C35: 1 | D35: 1
A36: QC 5 五廠品管 | B36: 4
A37: QC 6 六廠品管 | B37: 4
A38: QLK 2 二廠倉管部 | B38: 3
A39: QLK 4 四廠倉庫 | B39: 10
A40: QLK 5 五廠倉管部 | B40: 9 | C40: 1 | D40: 1
A41: QLK 6 六廠倉管部 | B41: 5
A42: QLSX 1 一廠生管 | B42: 49 | C42: 8 | D42: 7
...

Sheet Total
A1: No. | B1: amount | C1: Dep | D1: Name | E1: USER | F1: ID (vpic1.com) | G1: ID (FILESERVER) | H1: Password | I1: Create date | J1: Disable | K1: Delete | L1: Check Dep | M1: Note | N1: Column1
A2: 1 | B2: 1 | C2: QLSX 1 一廠生管 | D2: =VLOOKUP(E2,Sheet3!$A$2:$D$6338,2,0) -> Lê Kim Cường | E2: #10437 | F2: ="VN"&RIGHT(E2,5) -> VN10437 | H2: IT@vpic1 | I2: 45415 | J2: 45806 | K2: 45806 | L2: =VLOOKUP(E2,DS!$A$2:$E$4398, 5, 0) -> #N/A
A3: 2 | B3: 2 | C3: QLSX 1 一廠生管 | D3: =VLOOKUP(E3,Sheet3!$A$2:$D$6338,2,0) -> Nguyễn Thị Thu Hương | E3: #00328 | F3: ="VN"&RIGHT(E3,5) -> VN00328 | H3: IT@vpic1 | I3: 45415 | L3: =VLOOKUP(E3,DS!$A$2:$E$4398, 5, 0) -> QLSX | N3: =VLOOKUP(Table1[[#This Row],[USER]],[1]!Table145678910111213141545678910111213146[[#All],[No.]:[Delete]],2,0) -> #N/A
A4: 3 | B4: 3 | C4: QLSX 1 一廠生管 | D4: =VLOOKUP(E4,Sheet3!$A$2:$D$6338,2,0) -> Nguyễn Tuấn Anh | E4: #00527 | F4: ="VN"&RIGHT(E4,5) -> VN00527 | H4: IT@vpic1 | I4: 45415 | J4: 45530 | K4: 45530 | L4: =VLOOKUP(E4,DS!$A$2:$E$4398, 5, 0) -> #N/A | N4: =VLOOKUP(Table1[[#This Row],[USER]],[1]!Table145678910111213141545678910111213146[[#All],[No.]:[Delete]],2,0) -> #N/A
A5: 4 | B5: 4 | C5: QLSX 1 一廠生管 | D5: =VLOOKUP(E5,Sheet3!$A$2:$D$6338,2,0) -> Nguyễn Công Chính | E5: #00854 | F5: ="VN"&RIGHT(E5,5) -> VN00854 | H5: IT@vpic1 | I5: 45530 | L5: =VLOOKUP(E5,DS!$A$2:$E$4398, 5, 0) -> QLSX | N5: =VLOOKUP(Table1[[#This Row],[USER]],[1]!Table145678910111213141545678910111213146[[#All],[No.]:[Delete]],2,0) -> #N/A
A6: 5 | B6: 5 | C6: QLSX 1 一廠生管 | D6: =VLOOKUP(E6,Sheet3!$A$2:$D$6338,2,0) -> Kiều Văn Hiên | E6: #04202 | F6: ="VN"&RIGHT(E6,5) -> VN04202 | H6: IT@vpic1 | I6: 45415 | L6: =VLOOKUP(E6,DS!$A$2:$E$4398, 5, 0) -> QLSX | N6: =VLOOKUP(Table1[[#This Row],[USER]],[1]!Table145678910111213141545678910111213146[[#All],[No.]:[Delete]],2,0) -> #N/A
A7: 6 | B7: 6 | C7: QLSX 1 一廠生管 | D7: =VLOOKUP(E7,Sheet3!$A$2:$D$6338,2,0) -> Nguyễn Thị Thịnh | E7: #07789 | F7: ="VN"&RIGHT(E7,5) -> VN07789 | H7: IT@vpic1 | I7: 45415 | L7: =VLOOKUP(E7,DS!$A$2:$E$4398, 5, 0) -> QLSX | N7: =VLOOKUP(Table1[[#This Row],[USER]],[1]!Table145678910111213141545678910111213146[[#All],[No.]:[Delete]],2,0) -> #N/A
A8: 7 | B8: 7 | C8: QLSX 1 一廠生管 | D8: =VLOOKUP(E8,Sheet3!$A$2:$D$6338,2,0) -> Phan Thị Phượng | E8: #13582 | F8: ="VN"&RIGHT(E8,5) -> VN13582 | H8: IT@vpic1 | I8: 45415 | L8: =VLOOKUP(E8,DS!$A$2:$E$4398, 5, 0) -> QLSX | N8: =VLOOKUP(Table1[[#This Row],[USER]],[1]!Table145678910111213141545678910111213146[[#All],[No.]:[Delete]],2,0) -> #N/A
A9: 8 | B9: 8 | C9: QLSX 1 一廠生管 | D9: =VLOOKUP(E9,Sheet3!$A$2:$D$6338,2,0) -> Bùi Thị Thanh | E9: #08550 | F9: ="VN"&RIGHT(E9,5) -> VN08550 | H9: IT@vpic1 | I9: 45415 | L9: =VLOOKUP(E9,DS!$A$2:$E$4398, 5, 0) -> QLSX | N9: =VLOOKUP(Table1[[#This Row],[USER]],[1]!Table145678910111213141545678910111213146[[#All],[No.]:[Delete]],2,0) -> #N/A
A10: 9 | B10: 9 | C10: QLSX 1 一廠生管 | D10: =VLOOKUP(E10,Sheet3!$A$2:$D$6338,2,0) -> Nguyễn Thành Đồng | E10: #07290 | F10: ="VN"&RIGHT(E10,5) -> VN07290 | H10: IT@vpic1 | I10: 45415 | L10: =VLOOKUP(E10,DS!$A$2:$E$4398, 5, 0) -> QLSX | N10: =VLOOKUP(Table1[[#This Row],[USER]],[1]!Table145678910111213141545678910111213146[[#All],[No.]:[Delete]],2,0) -> #N/A
A11: 10 | B11: 10 | C11: QLSX 1 一廠生管 | D11: =VLOOKUP(E11,Sheet3!$A$2:$D$6338,2,0) -> Nguyễn Thị Minh Yến | E11: #08759 | F11: ="VN"&RIGHT(E11,5) -> VN08759 | H11: IT@vpic1 | I11: 45415 | J11: 45876 | K11: 45876 | L11: =VLOOKUP(E11,DS!$A$2:$E$4398, 5, 0) -> #N/A | N11: =VLOOKUP(Table1[[#This Row],[USER]],[1]!Table145678910111213141545678910111213146[[#All],[No.]:[Delete]],2,0) -> #N/A
A12: 11 | B12: 11 | C12: QLSX 1 一廠生管 | D12: =VLOOKUP(E12,Sheet3!$A$2:$D$6338,2,0) -> Lê Văn Bình | E12: #02245 | F12: ="VN"&RIGHT(E12,5) -> VN02245 | H12: IT@vpic1 | I12: 45415 | J12: 45530 | K12: 45806 | L12: =VLOOKUP(E12,DS!$A$2:$E$4398, 5, 0) -> #N/A | N12: =VLOOKUP(Table1[[#This Row],[USER]],[1]!Table145678910111213141545678910111213146[[#All],[No.]:[Delete]],2,0) -> #N/A
A13: 12 | B13: 12 | C13: QLSX 1 一廠生管 | D13: =VLOOKUP(E13,Sheet3!$A$2:$D$6338,2,0) -> Nguyễn Thị Mai | E13: #15884 | F13: ="VN"&RIGHT(E13,5) -> VN15884 | H13: IT@vpic1 | I13: 45415 | L13: =VLOOKUP(E13,DS!$A$2:$E$4398, 5, 0) -> QLSX | N13: =VLOOKUP(Table1[[#This Row],[USER]],[1]!Table145678910111213141545678910111213146[[#All],[No.]:[Delete]],2,0) -> #N/A
A14: 13 | B14: 13 | C14: QLSX 1 一廠生管 | D14: =VLOOKUP(E14,Sheet3!$A$2:$D$6338,2,0) -> Nguyễn Đình Tuấn | E14: #00665 | F14: ="VN"&RIGHT(E14,5) -> VN00665 | H14: IT@vpic1 | I14: 45415 | L14: =VLOOKUP(E14,DS!$A$2:$E$4398, 5, 0) -> QLSX | N14: =VLOOKUP(Table1[[#This Row],[USER]],[1]!Table145678910111213141545678910111213146[[#All],[No.]:[Delete]],2,0) -> #N/A
A15: 14 | B15: 14 | C15: QLSX 1 一廠生管 | D15: =VLOOKUP(E15,Sheet3!$A$2:$D$6338,2,0) -> Nguyễn Văn Mạnh | E15: #06748 | F15: ="VN"&RIGHT(E15,5) -> VN06748 | H15: IT@vpic1 | I15: 45415 | L15: =VLOOKUP(E15,DS!$A$2:$E$4398, 5, 0) -> QLSX | N15: =VLOOKUP(Table1[[#This Row],[USER]],[1]!Table145678910111213141545678910111213146[[#All],[No.]:[Delete]],2,0) -> #N/A
A16: 15 | B16: 15 | C16: QLSX 1 一廠生管 | D16: =VLOOKUP(E16,Sheet3!$A$2:$D$6338,2,0) -> Nguyễn Văn Thắng | E16: #03500 | F16: ="VN"&RIGHT(E16,5) -> VN03500 | H16: IT@vpic1 | I16: 45415 | J16: 45950 | K16: 45960 | L16: =VLOOKUP(E16,DS!$A$2:$E$4398, 5, 0) -> QLSX | N16: =VLOOKUP(Table1[[#This Row],[USER]],[1]!Table145678910111213141545678910111213146[[#All],[No.]:[Delete]],2,0) -> #N/A
A17: 16 | B17: 16 | C17: QLSX 1 一廠生管 | D17: =VLOOKUP(E17,Sheet3!$A$2:$D$6338,2,0) -> Đỗ Minh Hải | E17: #15725 | F17: ="VN"&RIGHT(E17,5) -> VN15725 | H17: IT@vpic1 | I17: 45415 | L17: =VLOOKUP(E17,DS!$A$2:$E$4398, 5, 0) -> QLSX | N17: =VLOOKUP(Table1[[#This Row],[USER]],[1]!Table145678910111213141545678910111213146[[#All],[No.]:[Delete]],2,0) -> #N/A
A18: 17 | B18: 17 | C18: QLSX 1 一廠生管 | D18: =VLOOKUP(E18,Sheet3!$A$2:$D$6338,2,0) -> Lê Văn Bảo | E18: #00186 | F18: ="VN"&RIGHT(E18,5) -> VN00186 | H18: IT@vpic1 | I18: 45415 | L18: =VLOOKUP(E18,DS!$A$2:$E$4398, 5, 0) -> QLSX | N18: =VLOOKUP(Table1[[#This Row],[USER]],[1]!Table145678910111213141545678910111213146[[#All],[No.]:[Delete]],2,0) -> #N/A
A19: 18 | B19: 18 | C19: QLSX 1 一廠生管 | D19: =VLOOKUP(E19,Sheet3!$A$2:$D$6338,2,0) -> Nguyễn Văn Nghiêm | E19: #04427 | F19: ="VN"&RIGHT(E19,5) -> VN04427 | H19: IT@vpic1 | I19: 45415 | L19: =VLOOKUP(E19,DS!$A$2:$E$4398, 5, 0) -> QLSX | N19: =VLOOKUP(Table1[[#This Row],[USER]],[1]!Table145678910111213141545678910111213146[[#All],[No.]:[Delete]],2,0) -> #N/A
A20: 19 | B20: 19 | C20: QLSX 1 一廠生管 | D20: =VLOOKUP(E20,Sheet3!$A$2:$D$6338,2,0) -> Nguyễn Thế Mạnh | E20: #01534 | F20: ="VN"&RIGHT(E20,5) -> VN01534 | H20: IT@vpic1 | I20: 45415 | L20: =VLOOKUP(E20,DS!$A$2:$E$4398, 5, 0) -> QLSX | N20: =VLOOKUP(Table1[[#This Row],[USER]],[1]!Table145678910111213141545678910111213146[[#All],[No.]:[Delete]],2,0) -> #N/A
A21: 20 | B21: 20 | C21: QLSX 1 一廠生管 | D21: =VLOOKUP(E21,Sheet3!$A$2:$D$6338,2,0) -> Nguyễn Tùng Lâm | E21: #15726 | F21: ="VN"&RIGHT(E21,5) -> VN15726 | H21: IT@vpic1 | I21: 45415 | L21: =VLOOKUP(E21,DS!$A$2:$E$4398, 5, 0) -> QLSX | N21: =VLOOKUP(Table1[[#This Row],[USER]],[1]!Table145678910111213141545678910111213146[[#All],[No.]:[Delete]],2,0) -> #N/A
A22: 21 | B22: 21 | C22: QLSX 1 一廠生管 | D22: =VLOOKUP(E22,Sheet3!$A$2:$D$6338,2,0) -> Nguyễn Trung Hiếu | E22: #09145 | F22: ="VN"&RIGHT(E22,5) -> VN09145 | H22: IT@vpic1 | I22: 45415 | L22: =VLOOKUP(E22,DS!$A$2:$E$4398, 5, 0) -> QLSX | N22: =VLOOKUP(Table1[[#This Row],[USER]],[1]!Table145678910111213141545678910111213146[[#All],[No.]:[Delete]],2,0) -> #N/A
A23: 22 | B23: 22 | C23: QLSX 1 一廠生管 | D23: =VLOOKUP(E23,Sheet3!$A$2:$D$6338,2,0) -> Lò Duy Chính | E23: #24335 | F23: ="VN"&RIGHT(E23,5) -> VN24335 | H23: IT@vpic1 | I23: 45442 | L23: =VLOOKUP(E23,DS!$A$2:$E$4398, 5, 0) -> QLSX | N23: =VLOOKUP(Table1[[#This Row],[USER]],[1]!Table145678910111213141545678910111213146[[#All],[No.]:[Delete]],2,0) -> #N/A
A24: 23 | B24: 23 | C24: QLSX 1 一廠生管 | D24: =VLOOKUP(E24,Sheet3!$A$2:$D$6338,2,0) -> Trần Văn Nam | E24: #24687 | F24: ="VN"&RIGHT(E24,5) -> VN24687 | H24: IT@vpic1 | I24: 45442 | J24: 45806 | K24: 45806 | L24: =VLOOKUP(E24,DS!$A$2:$E$4398, 5, 0) -> #N/A | N24: =VLOOKUP(Table1[[#This Row],[USER]],[1]!Table145678910111213141545678910111213146[[#All],[No.]:[Delete]],2,0) -> #N/A
A25: 24 | B25: 24 | C25: QLSX 1 一廠生管 | D25: =VLOOKUP(E25,Sheet3!$A$2:$D$6338,2,0) -> Nguyễn Mạnh Toàn | E25: #03747 | F25: ="VN"&RIGHT(E25,5) -> VN03747 | H25: IT@vpic1 | I25: 45415 | L25: =VLOOKUP(E25,DS!$A$2:$E$4398, 5, 0) -> QLSX | N25: =VLOOKUP(Table1[[#This Row],[USER]],[1]!Table145678910111213141545678910111213146[[#All],[No.]:[Delete]],2,0) -> #N/A
A26: 25 | B26: 25 | C26: QLSX 1 一廠生管 | D26: =VLOOKUP(E26,Sheet3!$A$2:$D$6338,2,0) -> Nguyễn Văn Mỹ | E26: #04428 | F26: ="VN"&RIGHT(E26,5) -> VN04428 | H26: IT@vpic1 | I26: 45415 | L26: =VLOOKUP(E26,DS!$A$2:$E$4398, 5, 0) -> QLSX | N26: =VLOOKUP(Table1[[#This Row],[USER]],[1]!Table145678910111213141545678910111213146[[#All],[No.]:[Delete]],2,0) -> #N/A
A27: 26 | B27: 26 | C27: QLSX 1 一廠生管 | D27: =VLOOKUP(E27,Sheet3!$A$2:$D$6338,2,0) -> Bùi Thị Xuyến | E27: #20328 | F27: ="VN"&RIGHT(E27,5) -> VN20328 | H27: IT@vpic1 | I27: 45415 | L27: =VLOOKUP(E27,DS!$A$2:$E$4398, 5, 0) -> QLSX | N27: =VLOOKUP(Table1[[#This Row],[USER]],[1]!Table145678910111213141545678910111213146[[#All],[No.]:[Delete]],2,0) -> #N/A
A28: 27 | B28: 27 | C28: QLSX 1 一廠生管 | D28: =VLOOKUP(E28,Sheet3!$A$2:$D$6338,2,0) -> Nguyễn Đức Thịnh | E28: #03613 | F28: ="VN"&RIGHT(E28,5) -> VN03613 | H28: IT@vpic1 | I28: 45415 | L28: =VLOOKUP(E28,DS!$A$2:$E$4398, 5, 0) -> QLSX | N28: =VLOOKUP(Table1[[#This Row],[USER]],[1]!Table145678910111213141545678910111213146[[#All],[No.]:[Delete]],2,0) -> #N/A
A29: 28 | B29: 28 | C29: QLSX 1 一廠生管 | D29: =VLOOKUP(E29,Sheet3!$A$2:$D$6338,2,0) -> Nguyễn Duy Tiến | E29: #06908 | F29: ="VN"&RIGHT(E29,5) -> VN06908 | H29: IT@vpic1 | I29: 45415 | L29: =VLOOKUP(E29,DS!$A$2:$E$4398, 5, 0) -> QLSX | N29: =VLOOKUP(Table1[[#This Row],[USER]],[1]!Table145678910111213141545678910111213146[[#All],[No.]:[Delete]],2,0) -> #N/A
A30: 29 | B30: 29 | C30: QLSX 1 一廠生管 | D30: =VLOOKUP(E30,Sheet3!$A$2:$D$6338,2,0) -> Nguyễn Thế Anh Tùng | E30: #19767 | F30: ="VN"&RIGHT(E30,5) -> VN19767 | H30: IT@vpic1 | I30: 45415 | J30: 45839 | K30: 45839 | L30: =VLOOKUP(E30,DS!$A$2:$E$4398, 5, 0) -> #N/A | N30: =VLOOKUP(Table1[[#This Row],[USER]],[1]!Table145678910111213141545678910111213146[[#All],[No.]:[Delete]],2,0) -> #N/A
A31: 30 | B31: 30 | C31: QLK | D31: =VLOOKUP(E31,Sheet3!$A$2:$D$6338,2,0) -> Phạm Quốc Doanh | E31: #12694 | F31: ="VN"&RIGHT(E31,5) -> VN12694 | H31: IT@vpic1 | I31: 45415 | L31: =VLOOKUP(E31,DS!$A$2:$E$4398, 5, 0) -> QLK | N31: =VLOOKUP(Table1[[#This Row],[USER]],[1]!Table145678910111213141545678910111213146[[#All],[No.]:[Delete]],2,0) -> #N/A
A32: 31 | B32: 31 | C32: QLSX 1 一廠生管 | D32: =VLOOKUP(E32,Sheet3!$A$2:$D$6338,2,0) -> Đỗ Mai Thoan | E32: #01232 | F32: ="VN"&RIGHT(E32,5) -> VN01232 | H32: IT@vpic1 | I32: 45415 | L32: =VLOOKUP(E32,DS!$A$2:$E$4398, 5, 0) -> QLSX | N32: =VLOOKUP(Table1[[#This Row],[USER]],[1]!Table145678910111213141545678910111213146[[#All],[No.]:[Delete]],2,0) -> #N/A
A33: 32 | B33: 32 | C33: QLSX 1 一廠生管 | D33: =VLOOKUP(E33,Sheet3!$A$2:$D$6338,2,0) -> Lê Thị Huyền | E33: #10788 | F33: ="VN"&RIGHT(E33,5) -> VN10788 | H33: IT@vpic1 | I33: 45415 | L33: =VLOOKUP(E33,DS!$A$2:$E$4398, 5, 0) -> Thu mua | N33: =VLOOKUP(Table1[[#This Row],[USER]],[1]!Table145678910111213141545678910111213146[[#All],[No.]:[Delete]],2,0) -> #N/A
A34: 33 | B34: 33 | C34: QLSX 1 一廠生管 | D34: =VLOOKUP(E34,Sheet3!$A$2:$D$6338,2,0) -> Phạm Minh Tuấn | E34: #10029 | F34: ="VN"&RIGHT(E34,5) -> VN10029 | H34: IT@vpic1 | I34: 45415 | L34: =VLOOKUP(E34,DS!$A$2:$E$4398, 5, 0) -> QLSX | N34: =VLOOKUP(Table1[[#This Row],[USER]],[1]!Table145678910111213141545678910111213146[[#All],[No.]:[Delete]],2,0) -> #N/A
A35: 34 | B35: 34 | C35: QLSX 1 一廠生管 | D35: =VLOOKUP(E35,Sheet3!$A$2:$D$6338,2,0) -> Nguyễn Thị Lữ | E35: #00767 | F35: ="VN"&RIGHT(E35,5) -> VN00767 | H35: IT@vpic1 | I35: 45415 | L35: =VLOOKUP(E35,DS!$A$2:$E$4398, 5, 0) -> QLSX | N35: =VLOOKUP(Table1[[#This Row],[USER]],[1]!Table145678910111213141545678910111213146[[#All],[No.]:[Delete]],2,0) -> #N/A
A36: 35 | B36: 35 | C36: QLSX 1 一廠生管 | D36: =VLOOKUP(E36,Sheet3!$A$2:$D$6338,2,0) -> Dương Văn Chiến | E36: #11937 | F36: ="VN"&RIGHT(E36,5) -> VN11937 | H36: IT@vpic1 | I36: 45415 | L36: =VLOOKUP(E36,DS!$A$2:$E$4398, 5, 0) -> QLSX | N36: =VLOOKUP(Table1[[#This Row],[USER]],[1]!Table145678910111213141545678910111213146[[#All],[No.]:[Delete]],2,0) -> #N/A
A37: 36 | B37: 36 | C37: Sơn 1 一廠塗裝 | D37: =VLOOKUP(E37,Sheet3!$A$2:$D$6338,2,0) -> Nguyễn Văn Tùng | E37: #24016 | F37: ="VN"&RIGHT(E37,5) -> VN24016 | H37: IT@vpic1 | I37: 45443 | L37: =VLOOKUP(E37,DS!$A$2:$E$4398, 5, 0) -> Sơn X1 | N37: =VLOOKUP(Table1[[#This Row],[USER]],[1]!Table145678910111213141545678910111213146[[#All],[No.]:[Delete]],2,0) -> #N/A
A38: 37 | B38: 37 | C38: QLSX 1 一廠生管 | D38: =VLOOKUP(E38,Sheet3!$A$2:$D$6338,2,0) -> Đỗ Thanh Tùng | E38: #24009 | F38: ="VN"&RIGHT(E38,5) -> VN24009 | H38: IT@vpic1 | I38: 45415 | L38: =VLOOKUP(E38,DS!$A$2:$E$4398, 5, 0) -> QLSX | N38: =VLOOKUP(Table1[[#This Row],[USER]],[1]!Table145678910111213141545678910111213146[[#All],[No.]:[Delete]],2,0) -> #N/A
A39: 38 | B39: 38 | C39: QLSX 1 一廠生管 | D39: =VLOOKUP(E39,Sheet3!$A$2:$D$6338,2,0) -> Nguyễn Duy Hiển | E39: #19909 | F39: ="VN"&RIGHT(E39,5) -> VN19909 | H39: IT@vpic1 | I39: 45415 | L39: =VLOOKUP(E39,DS!$A$2:$E$4398, 5, 0) -> QLSX | N39: =VLOOKUP(Table1[[#This Row],[USER]],[1]!Table145678910111213141545678910111213146[[#All],[No.]:[Delete]],2,0) -> #N/A
A40: 39 | B40: 39 | C40: QLSX 1 一廠生管 | D40: =VLOOKUP(E40,Sheet3!$A$2:$D$6338,2,0) -> Nguyễn Minh Tuân | E40: #02547 | F40: ="VN"&RIGHT(E40,5) -> VN02547 | H40: IT@vpic1 | I40: 45415 | L40: =VLOOKUP(E40,DS!$A$2:$E$4398, 5, 0) -> QLSX | N40: =VLOOKUP(Table1[[#This Row],[USER]],[1]!Table145678910111213141545678910111213146[[#All],[No.]:[Delete]],2,0) -> #N/A
...

Sheet Sheet3
A1: *Account | B1: *Name
A2: DL19 | B2: 吳聰武
A3: DL01 | B3: 詹文龍
A4: DL05 | B4: 廖仁成
A5: #00336 | B5: Vũ Thị Nhinh
A6: #00498 | B6: Nguyễn Thị Thêu
A7: #01789 | B7: Ngô Thị Dịu
A8: #02119 | B8: Trần Thị Anh
A9: #08882 | B9: Nguyễn Thị Hường
A10: #18985 | B10: Nguyễn Văn Phúc
A11: #19165 | B11: Chu Thị Thảo
A12: #20364 | B12: Lưu Thị Vượng
... A6338: #25022 | B6338: Nguyễn Viết Việt

Sheet Sheet4
A1: No. | B1: amount | C1: Dep | D1: Name | E1: USER | F1: ID (vpic1.com) | G1: ID (FILESERVER) | H1: Email Local | I1: Tiến độ | J1: Password | K1: Create date | L1: Disable | M1: Delete | N1: Check Dep | O1: Note
A2: 298 | B2: 1 | C2: An toàn - Môi trường 安環室 | D2: Nguyễn Minh Tâm | E2: #01443 | F2: VN01443 | G2: =VLOOKUP(E2,Table145678910111213141545678910111213146[[CODE]:[Email Local]],4,0) -> amt.01443 | H2: =VLOOKUP(E2,Table145678910111213141545678910111213146[[CODE]:[Email Local]],6,0) -> 0 | I2: Hoàn thành | J2: IT@vpic1 | K2: 45404 | N2: ATMT
A3: 299 | B3: 2 | C3: An toàn - Môi trường 安環室 | D3: Bùi Thị Nguyên | E3: #03502 | F3: VN03502 | G3: =VLOOKUP(E3,Table145678910111213141545678910111213146[[CODE]:[Email Local]],4,0) -> amt.03502 | H3: =VLOOKUP(E3,Table145678910111213141545678910111213146[[CODE]:[Email Local]],6,0) -> 0 | I3: Hoàn thành | J3: IT@vpic1 | K3: 45404 | N3: ATMT
A4: 301 | B4: 4 | C4: An toàn - Môi trường 安環室 | D4: #N/A | E4: #16850 | F4: VN16850 | G4: =VLOOKUP(E4,Table145678910111213141545678910111213146[[CODE]:[Email Local]],4,0) -> #N/A | H4: =VLOOKUP(E4,Table145678910111213141545678910111213146[[CODE]:[Email Local]],6,0) -> #N/A | I4: Hoàn thành | J4: IT@vpic1 | K4: 45404 | L4: 45729 | M4: 45729 | N4: #N/A
A5: 302 | B5: 5 | C5: An toàn - Môi trường 安環室 | D5: Nguyễn Văn Kiên | E5: #24122 | F5: VN24122 | G5: =VLOOKUP(E5,Table145678910111213141545678910111213146[[CODE]:[Email Local]],4,0) -> #N/A | H5: =VLOOKUP(E5,Table145678910111213141545678910111213146[[CODE]:[Email Local]],6,0) -> #N/A | I5: Hoàn thành | J5: IT@vpic1 | K5: 45404 | L5: 45806 | M5: 45806 | N5: #N/A
A6: 303 | B6: 6 | C6: An toàn - Môi trường 安環室 | D6: Nguyễn Anh Tuấn | E6: #03618 | F6: VN03618 | G6: =VLOOKUP(E6,Table145678910111213141545678910111213146[[CODE]:[Email Local]],4,0) -> amt.03618 | H6: =VLOOKUP(E6,Table145678910111213141545678910111213146[[CODE]:[Email Local]],6,0) -> 0 | I6: Hoàn thành | J6: IT@vpic1 | K6: 45404 | N6: ATMT
A7: 304 | B7: 7 | C7: An toàn - Môi trường 安環室 | D7: Trần Văn Sơn | E7: #22261 | F7: VN22261 | G7: =VLOOKUP(E7,Table145678910111213141545678910111213146[[CODE]:[Email Local]],4,0) -> amt.22261 | H7: =VLOOKUP(E7,Table145678910111213141545678910111213146[[CODE]:[Email Local]],6,0) -> 0 | I7: Hoàn thành | J7: IT@vpic1 | K7: 45404 | L7: 45432 | M7: 45481 | N7: #N/A
A8: 305 | B8: 8 | C8: An toàn - Môi trường 安環室 | D8: Chu Thanh Sơn | E8: #25127 | F8: VN25127 | G8: =VLOOKUP(E8,Table145678910111213141545678910111213146[[CODE]:[Email Local]],4,0) -> 25127.son | H8: =VLOOKUP(E8,Table145678910111213141545678910111213146[[CODE]:[Email Local]],6,0) -> 0 | I8: Hoàn thành | J8: IT@vpic1 | K8: 45509 | N8: ATMT
A9: 306 | B9: 8 | C9: An toàn - Môi trường 安環室 | D9: Tạ Hải Anh | E9: #25148 | F9: VN25148 | G9: =VLOOKUP(E9,Table145678910111213141545678910111213146[[CODE]:[Email Local]],4,0) -> 25148.anh | H9: =VLOOKUP(E9,Table145678910111213141545678910111213146[[CODE]:[Email Local]],6,0) -> 0 | I9: Hoàn thành | J9: IT@vpic1 | K9: 45807 | N9: ATMT
A10: 307 | B10: 9 | C10: An toàn - Môi trường 安環室 | D10: Nguyễn Huỳnh Đức | E10: #25678 | F10: VN25678 | G10: =VLOOKUP(E10,Table145678910111213141545678910111213146[[CODE]:[Email Local]],4,0) -> 25678.duc | H10: =VLOOKUP(E10,Table145678910111213141545678910111213146[[CODE]:[Email Local]],6,0) -> 0 | I10: Hoàn thành | J10: IT@vpic1 | K10: 45729 | N10: ATMT
A11: 300 | B11: 3 | C11: An toàn - Môi trường 安環室 | D11: Hà Trung Kiên | E11: #15950 | F11: VN15950 | G11: =VLOOKUP(E11,Table145678910111213141545678910111213146[[CODE]:[Email Local]],4,0) -> amt.15950 | H11: =VLOOKUP(E11,Table145678910111213141545678910111213146[[CODE]:[Email Local]],6,0) -> ok | I11: Hoàn thành | J11: IT@vpic1 | K11: 45404 | N11: ATMT
A12: 636 | B12: 1 | C12: Cán ống 製管事業部 | D12: Trần Hữu Hoàn | E12: #15013 | F12: VN15013 | G12: =VLOOKUP(E12,Table145678910111213141545678910111213146[[CODE]:[Email Local]],4,0) -> #N/A | H12: =VLOOKUP(E12,Table145678910111213141545678910111213146[[CODE]:[Email Local]],6,0) -> #N/A | I12: Hoàn thành | J12: IT@vpic1 | K12: 45435 | N12: Cán ống
A13: 133 | B13: 3 | C13: Cắt 3 三 廠素材 | D13: Nguyễn Văn Sơn | E13: #08917 | F13: VN08917 | G13: =VLOOKUP(E13,Table145678910111213141545678910111213146[[CODE]:[Email Local]],4,0) -> 08917.son | H13: =VLOOKUP(E13,Table145678910111213141545678910111213146[[CODE]:[Email Local]],6,0) -> 0 | I13: Hoàn thành | J13: IT@vpic1 | K13: 45432 | N13: Cắt X3
A14: 136 | B14: 5 | C14: Cắt 3 三 廠素材 | D14: Trần Văn Dũng | E14: #15502 | F14: VN15502 | G14: =VLOOKUP(E14,Table145678910111213141545678910111213146[[CODE]:[Email Local]],4,0) -> cat.15502 | H14: =VLOOKUP(E14,Table145678910111213141545678910111213146[[CODE]:[Email Local]],6,0) -> 0 | I14: Hoàn thành | J14: IT@vpic1 | K14: 45432 | L14: 45806 | M14: 45807 | N14: #N/A
A15: 137 | B15: 6 | C15: Cắt 3 三 廠素材 | D15: Nguyễn Thị Phương Thảo | E15: #07839 | F15: VN07839 | G15: =VLOOKUP(E15,Table145678910111213141545678910111213146[[CODE]:[Email Local]],4,0) -> cat.07839 | H15: =VLOOKUP(E15,Table145678910111213141545678910111213146[[CODE]:[Email Local]],6,0) -> 0 | I15: Hoàn thành | J15: IT@vpic1 | K15: 45432 | L15: 45806 | M15: 45807 | N15: #N/A
A16: 139 | B16: 8 | C16: Cắt 3 三 廠素材 | D16: Chu Văn Tư | E16: #07286 | F16: VN07286 | G16: =VLOOKUP(E16,Table145678910111213141545678910111213146[[CODE]:[Email Local]],4,0) -> cat.07286 | H16: =VLOOKUP(E16,Table145678910111213141545678910111213146[[CODE]:[Email Local]],6,0) -> 0 | I16: Hoàn thành | J16: IT@vpic1 | K16: 45432 | N16: Cắt Laser
A17: 132 | B17: 2 | C17: Cắt 3 三 廠素材 | D17: Nguyễn Thị Thuận | E17: #19230 | F17: VN19230 | G17: =VLOOKUP(E17,Table145678910111213141545678910111213146[[CODE]:[Email Local]],4,0) -> cat.19230 | H17: =VLOOKUP(E17,Table145678910111213141545678910111213146[[CODE]:[Email Local]],6,0) -> ok | I17: Hoàn thành | J17: IT@vpic1 | K17: 45432 | N17: Cắt X3
A18: 134 | B18: 4 | C18: Cắt 3 三 廠素材 | D18: Lâm Thị Hiền | E18: #02857 | F18: VN02857 | G18: =VLOOKUP(E18,Table145678910111213141545678910111213146[[CODE]:[Email Local]],4,0) -> cat.02857 | H18: =VLOOKUP(E18,Table145678910111213141545678910111213146[[CODE]:[Email Local]],6,0) -> ok | I18: Hoàn thành | J18: IT@vpic1 | K18: 45432 | N18: Cắt X3
A19: 138 | B19: 7 | C19: Cắt 3 三 廠素材 | D19: Đường Văn Mạnh | E19: #00868 | F19: VN00868 | G19: =VLOOKUP(E19,Table145678910111213141545678910111213146[[CODE]:[Email Local]],4,0) -> cat.00868 | H19: =VLOOKUP(E19,Table145678910111213141545678910111213146[[CODE]:[Email Local]],6,0) -> ok | I19: Hoàn thành | J19: IT@vpic1 | K19: 45432 | N19: Cắt X3
A20: 517 | B20: 1 | C20: Công Vụ 工務 | D20: Vũ Thanh Tùng | E20: #00213 | F20: VN00213 | G20: =VLOOKUP(E20,Table145678910111213141545678910111213146[[CODE]:[Email Local]],4,0) -> #N/A | H20: =VLOOKUP(E20,Table145678910111213141545678910111213146[[CODE]:[Email Local]],6,0) -> #N/A | J20: IT@vpic1 | K20: 45437 | N20: Công vụ
A21: 518 | B21: 2 | C21: Công Vụ 工務 | D21: Vũ Trường Giang | E21: #07948 | F21: VN07948 | G21: =VLOOKUP(E21,Table145678910111213141545678910111213146[[CODE]:[Email Local]],4,0) -> cvu.07948 | H21: =VLOOKUP(E21,Table145678910111213141545678910111213146[[CODE]:[Email Local]],6,0) -> 0 | J21: IT@vpic1 | K21: 45437 | N21: Công vụ
A22: 94 | B22: 1 | C22: Dập 1 一廠沖壓 | D22: Trần Ngọc Mạnh | E22: #07790 | F22: VN07790 | G22: =VLOOKUP(E22,Table145678910111213141545678910111213146[[CODE]:[Email Local]],4,0) -> dap1.07790 | H22: =VLOOKUP(E22,Table145678910111213141545678910111213146[[CODE]:[Email Local]],6,0) -> 0 | J22: IT@vpic1 | K22: 45421 | N22: Dập X1
A23: 95 | B23: 2 | C23: Dập 1 一廠沖壓 | D23: Nguyễn Thị Thanh Hương | E23: #16479 | F23: VN16479 | G23: =VLOOKUP(E23,Table145678910111213141545678910111213146[[CODE]:[Email Local]],4,0) -> #N/A | H23: =VLOOKUP(E23,Table145678910111213141545678910111213146[[CODE]:[Email Local]],6,0) -> #N/A | J23: IT@vpic1 | K23: 45421 | L23: 45876 | M23: 45876 | N23: #N/A
A24: 96 | B24: 3 | C24: Dập 1 一廠沖壓 | D24: Nguyễn Văn Thiệu | E24: #10988 | F24: VN10988 | G24: =VLOOKUP(E24,Table145678910111213141545678910111213146[[CODE]:[Email Local]],4,0) -> #N/A | H24: =VLOOKUP(E24,Table145678910111213141545678910111213146[[CODE]:[Email Local]],6,0) -> #N/A | J24: IT@vpic1 | K24: 45421 | L24: 45929 | M24: 45960 | N24: #N/A
A25: 97 | B25: 4 | C25: Dập 1 一廠沖壓 | D25: Đỗ Thị Hoa | E25: #03439 | F25: VN03439 | G25: =VLOOKUP(E25,Table145678910111213141545678910111213146[[CODE]:[Email Local]],4,0) -> #N/A | H25: =VLOOKUP(E25,Table145678910111213141545678910111213146[[CODE]:[Email Local]],6,0) -> #N/A | J25: IT@vpic1 | K25: 45421 | N25: Dập X1
A26: 99 | B26: 6 | C26: Dập 1 一廠沖壓 | D26: Đỗ Thị Thanh | E26: #17617 | F26: VN17617 | G26: =VLOOKUP(E26,Table145678910111213141545678910111213146[[CODE]:[Email Local]],4,0) -> #N/A | H26: =VLOOKUP(E26,Table145678910111213141545678910111213146[[CODE]:[Email Local]],6,0) -> #N/A | J26: IT@vpic1 | K26: 45421 | N26: Dập X1
A27: 101 | B27: 8 | C27: Dập 1 一廠沖壓 | D27: Dương Văn Tường | E27: #00254 | F27: VN00254 | G27: =VLOOKUP(E27,Table145678910111213141545678910111213146[[CODE]:[Email Local]],4,0) -> dap1.00254 | H27: =VLOOKUP(E27,Table145678910111213141545678910111213146[[CODE]:[Email Local]],6,0) -> 0 | J27: IT@vpic1 | K27: 45421 | N27: Dập X1
A28: 102 | B28: 9 | C28: Dập 1 一廠沖壓 | D28: Bùi Đình Tuyên | E28: #00765 | F28: VN00765 | G28: =VLOOKUP(E28,Table145678910111213141545678910111213146[[CODE]:[Email Local]],4,0) -> #N/A | H28: =VLOOKUP(E28,Table145678910111213141545678910111213146[[CODE]:[Email Local]],6,0) -> #N/A | J28: IT@vpic1 | K28: 45421 | L28: 45806 | M28: 45806 | N28: #N/A
A29: 103 | B29: 10 | C29: Dập 1 一廠沖壓 | D29: Phan Bá Tước | E29: #00487 | F29: VN00487 | G29: =VLOOKUP(E29,Table145678910111213141545678910111213146[[CODE]:[Email Local]],4,0) -> #N/A | H29: =VLOOKUP(E29,Table145678910111213141545678910111213146[[CODE]:[Email Local]],6,0) -> #N/A | J29: IT@vpic1 | K29: 45562 | N29: Dập X1
A30: 104 | B30: 11 | C30: Dập 1 一廠沖壓 | D30: Lương Văn Giang | E30: #00860 | F30: VN00860 | G30: =VLOOKUP(E30,Table145678910111213141545678910111213146[[CODE]:[Email Local]],4,0) -> #N/A | H30: =VLOOKUP(E30,Table145678910111213141545678910111213146[[CODE]:[Email Local]],6,0) -> #N/A | J30: IT@vpic1 | K30: 45741 | N30: Dập X1
A31: 105 | C31: Dập 1 一廠沖壓 | D31: Nguyễn Thị Minh Huệ | E31: #06955 | F31: VN06955 | G31: =VLOOKUP(E31,Table145678910111213141545678910111213146[[CODE]:[Email Local]],4,0) -> #N/A | H31: =VLOOKUP(E31,Table145678910111213141545678910111213146[[CODE]:[Email Local]],6,0) -> #N/A | J31: IT@vpic1 | K31: 45807 | N31: Dập X1
A32: 772 | C32: Dập 1 一廠沖壓 | D32: Đào Văn Thanh | E32: #03965 | F32: VN03965 | G32: =VLOOKUP(E32,Table145678910111213141545678910111213146[[CODE]:[Email Local]],4,0) -> #N/A | H32: =VLOOKUP(E32,Table145678910111213141545678910111213146[[CODE]:[Email Local]],6,0) -> #N/A | J32: IT@vpic1 | K32: "02-01-2026 | N32: Dập X1
A33: 98 | B33: 5 | C33: Dập 1 一廠沖壓 | D33: Trần Thị Thu Thuỷ | E33: #03094 | F33: VN03094 | G33: =VLOOKUP(E33,Table145678910111213141545678910111213146[[CODE]:[Email Local]],4,0) -> dap1.03094 | H33: =VLOOKUP(E33,Table145678910111213141545678910111213146[[CODE]:[Email Local]],6,0) -> ok | J33: IT@vpic1 | K33: 45421 | N33: Dập X1
A34: 100 | B34: 7 | C34: Dập 1 一廠沖壓 | D34: Tạ Hữu Bằng | E34: #00998 | F34: VN00998 | G34: =VLOOKUP(E34,Table145678910111213141545678910111213146[[CODE]:[Email Local]],4,0) -> 00998.bang | H34: =VLOOKUP(E34,Table145678910111213141545678910111213146[[CODE]:[Email Local]],6,0) -> ok | J34: IT@vpic1 | K34: 45421 | N34: Dập X1
A35: 140 | B35: 1 | C35: Dập 3 三廠沖壓 | D35: Hà Thị Thu Hà | E35: #21906 | F35: VN21906 | G35: =VLOOKUP(E35,Table145678910111213141545678910111213146[[CODE]:[Email Local]],4,0) -> #N/A | H35: =VLOOKUP(E35,Table145678910111213141545678910111213146[[CODE]:[Email Local]],6,0) -> #N/A | J35: IT@vpic1 | K35: 45432 | L35: 45929 | M35: 45929 | N35: #N/A
A36: 143 | B36: 4 | C36: Dập 3 三廠沖壓 | D36: Nguyễn Thị Phượng | E36: #09866 | F36: VN09866 | G36: =VLOOKUP(E36,Table145678910111213141545678910111213146[[CODE]:[Email Local]],4,0) -> dap3.9866 | H36: =VLOOKUP(E36,Table145678910111213141545678910111213146[[CODE]:[Email Local]],6,0) -> 0 | J36: IT@vpic1 | K36: 45432 | N36: Dập X3
A37: 144 | B37: 5 | C37: Dập 3 三廠沖壓 | D37: Nguyễn Thị Liêm | E37: #10367 | F37: VN10367 | G37: =VLOOKUP(E37,Table145678910111213141545678910111213146[[CODE]:[Email Local]],4,0) -> dap3.10367 | H37: =VLOOKUP(E37,Table145678910111213141545678910111213146[[CODE]:[Email Local]],6,0) -> 0 | J37: IT@vpic1 | K37: 45432 | N37: Dập X3
A38: 145 | B38: 6 | C38: Dập 3 三廠沖壓 | D38: Nguyễn Thị Kim Thoa | E38: #17741 | F38: VN17741 | G38: =VLOOKUP(E38,Table145678910111213141545678910111213146[[CODE]:[Email Local]],4,0) -> #N/A | H38: =VLOOKUP(E38,Table145678910111213141545678910111213146[[CODE]:[Email Local]],6,0) -> #N/A | J38: IT@vpic1 | K38: 45432 | N38: Dập X3
A39: 146 | B39: 7 | C39: Dập 3 三廠沖壓 | D39: Dương Đức Thắng | E39: #00677 | F39: VN00677 | G39: =VLOOKUP(E39,Table145678910111213141545678910111213146[[CODE]:[Email Local]],4,0) -> dap3.0677 | H39: =VLOOKUP(E39,Table145678910111213141545678910111213146[[CODE]:[Email Local]],6,0) -> 0 | J39: IT@vpic1 | K39: 45432 | N39: Dập X3
A40: 148 | C40: Dập 3 三廠沖壓 | D40: Nguyễn Trọng Hải Anh | E40: #26001 | F40: VN26001 | G40: =VLOOKUP(E40,Table145678910111213141545678910111213146[[CODE]:[Email Local]],4,0) -> #N/A | H40: =VLOOKUP(E40,Table145678910111213141545678910111213146[[CODE]:[Email Local]],6,0) -> #N/A | J40: IT@vpic1 | K40: 45839 | N40: Lắp ráp
...

Sheet DS
B1: Số thẻ chính thức | C1: Họ và Tên | D1: ngày vào | E1: Phòng
A2: ="#"&B2 -> #
A3: ="#"&B3 -> #
A4: ="#"&B4 -> #00038 | B4: 00038 | C4: Lê Văn Trưởng | D4: 37216 | E4: Hàn X1
A5: ="#"&B5 -> #00039 | B5: 00039 | C5: Nguyễn Văn Minh | D5: 37216 | E5: QC
A6: ="#"&B6 -> #00041 | B6: 00041 | C6: Nguyễn Văn Xuân | D6: 37217 | E6: QLK
A7: ="#"&B7 -> #00046 | B7: 00046 | C7: Nguyễn Quốc Hoàn | D7: 37222 | E7: Hàn X6
A8: ="#"&B8 -> #00056 | B8: 00056 | C8: Nguyễn Văn Bích | D8: 37312 | E8: QC
A9: ="#"&B9 -> #00063 | B9: 00063 | C9: Nguyễn Duy Dũng | D9: 37411 | E9: Sơn X3
A10: ="#"&B10 -> #00067 | B10: 00067 | C10: Nguyễn Anh Tiến | D10: 37411 | E10: Khuôn mẫu
A11: ="#"&B11 -> #00069 | B11: 00069 | C11: Nguyễn Hữu Thắng | D11: 37411 | E11: QLK
A12: ="#"&B12 -> #00072 | B12: 00072 | C12: Trần Đức Quang | D12: 37411 | E12: QLSX
A13: ="#"&B13 -> #00079 | B13: 00079 | C13: Phạm Thị Hồng Việt | D13: 37420 | E13: QC
A14: ="#"&B14 -> #00082 | B14: 00082 | C14: Lê Văn Duy | D14: 37439 | E14: Sơn X6
A15: ="#"&B15 -> #00110 | B15: 00110 | C15: Phạm Sỹ Vượng | D15: 37369 | E15: Hàn X1
... A4259: ="#"&B4259 -> #26461 | B4259: 26461 | C4259: Hoàng Quốc Việt | D4259: 45994 | E4259: Hàn X3
A4260: #26471 | B4260: 26471 | C4260: Nguyễn Thị Đan Quế | E4260: Thu mua

Sheet FileServer
A1: FILE SERVER UPDATE
A2: No. | B2: Num | C2: Department | D2: CODE | E2: Code2 | F2: FULL NAME | G2: USER | H2: ALOW AD | I2: Email Local | J2: Pass | K2: Create date | L2: Disable | M2: Delete | N2: Column1
A3: 1 | B3: 1 | C3: CAT | D3: =CONCATENATE("#",E3) -> #03441 | E3: 03441 | F3: Khổng Thị Thanh Tú | G3: cat.03441 | H3: =CONCATENATE("VN",E3) -> VN03441 | I3: ok
A4: 2 | B4: 2 | C4: CAT | D4: =CONCATENATE("#",E4) -> #07286 | E4: 07286 | F4: Chu Văn Tư | G4: cat.07286 | H4: =CONCATENATE("VN",E4) -> VN07286
A5: 3 | B5: 3 | C5: CAT | D5: =CONCATENATE("#",E5) -> #07839 | E5: 07839 | F5: Nguyễn Thị Phương Thảo | G5: cat.07839 | H5: =CONCATENATE("VN",E5) -> VN07839 | L5: 45784 | M5: 45887
A6: 4 | B6: 4 | C6: CAT | D6: =CONCATENATE("#",E6) -> #00868 | E6: 00868 | F6: Đường Văn Mạnh | G6: cat.00868 | H6: =CONCATENATE("VN",E6) -> VN00868 | I6: ok | J6: MaNH!@#00868
A7: 5 | B7: 5 | C7: CAT | D7: =CONCATENATE("#",E7) -> #01458 | E7: 01458 | F7: Nguyễn Văn Chúc | G7: cat.01458 | H7: =CONCATENATE("VN",E7) -> VN01458 | I7: CAT 素材
A8: 6 | B8: 6 | C8: CAT | D8: =CONCATENATE("#",E8) -> #02175 | E8: 02175 | F8: Trần Kim Thu | G8: cat.02175 | H8: =CONCATENATE("VN",E8) -> VN02175
A9: 7 | B9: 7 | C9: CAT | D9: =CONCATENATE("#",E9) -> #02319 | E9: 02319 | F9: Nguyễn Văn Nhất | G9: cat.02319 | H9: =CONCATENATE("VN",E9) -> VN02319
A10: 8 | B10: 8 | C10: CAT | D10: =CONCATENATE("#",E10) -> #15502 | E10: 15502 | F10: Trần Văn Dũng | G10: cat.15502 | H10: =CONCATENATE("VN",E10) -> VN15502 | L10: 45596 | M10: 45887
A11: 9 | B11: 9 | C11: CAT | D11: =CONCATENATE("#",E11) -> #08917 | E11: 08917 | F11: Nguyễn Văn Sơn | G11: 08917.son | H11: =CONCATENATE("VN",E11) -> VN08917 | J11: 123456 | K11: 45525
A12: 10 | B12: 10 | C12: CAT | D12: =CONCATENATE("#",E12) -> #02857 | E12: 02857 | F12: Lâm Thị Hiền | G12: cat.02857 | H12: =CONCATENATE("VN",E12) -> VN02857 | I12: ok
A13: 11 | B13: 11 | C13: CAT | D13: =CONCATENATE("#",E13) -> #19230 | E13: 19230 | F13: Nguyễn Thị Thuân | G13: cat.19230 | H13: =CONCATENATE("VN",E13) -> VN19230 | I13: ok
A14: 12 | B14: 1 | C14: DANH BONG | D14: =CONCATENATE("#",E14) -> #01614 | E14: 01614 | F14: Phùng Văn Hà | G14: son.01614 | H14: =CONCATENATE("VN",E14) -> VN01614
A15: 13 | B15: 2 | C15: DANH BONG | D15: =CONCATENATE("#",E15) -> #01021 | E15: 01021 | F15: Bùi Việt Anh | G15: db.01021 | H15: =CONCATENATE("VN",E15) -> VN01021 | I15: ok
A16: 14 | B16: 3 | C16: DANH BONG | D16: =CONCATENATE("#",E16) -> #09155 | E16: 09155 | F16: Đặng Văn Thái | G16: db.09155 | H16: =CONCATENATE("VN",E16) -> VN09155
A17: 15 | B17: 4 | C17: DANH BONG | D17: =CONCATENATE("#",E17) -> #01609 | E17: 01609 | F17: Ngô Đình Hiếu | G17: db.01609 | H17: =CONCATENATE("VN",E17) -> VN01609
A18: 16 | B18: 1 | C18: KAIFA | D18: =CONCATENATE("#",E18) -> #00285 | E18: 00285 | F18: Đàm Thị Kim Liên | G18: kf.00285 | H18: =CONCATENATE("VN",E18) -> VN00285
A19: 17 | B19: 2 | C19: KAIFA | D19: =CONCATENATE("#",E19) -> #00490 | E19: 00490 | F19: Hạ Văn Lợi | G19: kf.0490 | H19: =CONCATENATE("VN",E19) -> VN00490
A20: 18 | B20: 3 | C20: KAIFA | D20: =CONCATENATE("#",E20) -> #00799 | E20: 00799 | F20: Phan Bá Bộ | G20: kf.0799 | H20: =CONCATENATE("VN",E20) -> VN00799
A21: 19 | B21: 4 | C21: KAIFA | D21: =CONCATENATE("#",E21) -> #01057 | E21: 01057 | F21: Phạm Thế Sơn | G21: kf.1057 | H21: =CONCATENATE("VN",E21) -> VN01057
A22: 20 | B22: 5 | C22: KAIFA | D22: =CONCATENATE("#",E22) -> #01955 | E22: 01955 | F22: Dương Đức Sơn | G22: kf.1955 | H22: =CONCATENATE("VN",E22) -> VN01955
A23: 21 | B23: 6 | C23: KAIFA | D23: =CONCATENATE("#",E23) -> #02543 | E23: 02543 | F23: Hoàng văn Hải | G23: kf.2543 | H23: =CONCATENATE("VN",E23) -> VN02543
A24: 22 | B24: 7 | C24: KAIFA | D24: =CONCATENATE("#",E24) -> #02642 | E24: 02642 | F24: Phạm Văn Vẽ | G24: kf.2642 | H24: =CONCATENATE("VN",E24) -> VN02642 | J24: Vanve2642@
A25: 23 | B25: 8 | C25: KAIFA | D25: =CONCATENATE("#",E25) -> #03487 | E25: 03487 | F25: Nguyễn Đình Đường | G25: kf.3487 | H25: =CONCATENATE("VN",E25) -> VN03487
A26: 24 | B26: 9 | C26: KAIFA | D26: =CONCATENATE("#",E26) -> #03798 | E26: 03798 | F26: Phùng Hữu Đức | G26: kf.3798 | H26: =CONCATENATE("VN",E26) -> VN03798
A27: 25 | B27: 10 | C27: KAIFA | D27: =CONCATENATE("#",E27) -> #03889 | E27: 03889 | F27: Đỗ Tiến Mạnh | G27: kf.3889 | H27: =CONCATENATE("VN",E27) -> VN03889
A28: 26 | B28: 11 | C28: KAIFA | D28: =CONCATENATE("#",E28) -> #04750 | E28: 04750 | F28: Lương Văn Thường | G28: kf.4750 | H28: =CONCATENATE("VN",E28) -> VN04750
A29: 27 | B29: 12 | C29: KAIFA | D29: =CONCATENATE("#",E29) -> #04751 | E29: 04751 | F29: Hạ Trọng Lực | G29: kf.4751 | H29: =CONCATENATE("VN",E29) -> VN04751
A30: 28 | B30: 13 | C30: KAIFA | D30: =CONCATENATE("#",E30) -> #05224 | E30: 05224 | F30: Vũ Thị Thanh Hương | G30: kf.5224 | H30: =CONCATENATE("VN",E30) -> VN05224 | I30: ok
A31: 29 | B31: 14 | C31: KAIFA | D31: =CONCATENATE("#",E31) -> #06235 | E31: 06235 | F31: Nguyễn Đình Dũng | G31: kf.6235 | H31: =CONCATENATE("VN",E31) -> VN06235 | L31: 45735 | M31: 45887
A32: 30 | B32: 15 | C32: KAIFA | D32: =CONCATENATE("#",E32) -> #06382 | E32: 06382 | F32: Lê Văn Châm | G32: kf.6382 | H32: =CONCATENATE("VN",E32) -> VN06382
A33: 31 | B33: 16 | C33: KAIFA | D33: =CONCATENATE("#",E33) -> #07179 | E33: 07179 | F33: Phùng Văn Quyền | G33: kf.7179 | H33: =CONCATENATE("VN",E33) -> VN07179
A34: 32 | B34: 17 | C34: KAIFA | D34: =CONCATENATE("#",E34) -> #07837 | E34: 07837 | F34: Nghiêm Văn Dự | G34: kf.7837 | H34: =CONCATENATE("VN",E34) -> VN07837 | L34: 45672 | M34: 45887
A35: 33 | B35: 18 | C35: KAIFA | D35: =CONCATENATE("#",E35) -> #08125 | E35: 08125 | F35: Nguyễn Văn Thấm | G35: kf.8125 | H35: =CONCATENATE("VN",E35) -> VN08125 | L35: 45759 | M35: 45887
A36: 34 | B36: 19 | C36: KAIFA | D36: =CONCATENATE("#",E36) -> #08128 | E36: 08128 | F36: Phùng Văn Phương | G36: kf.8128 | H36: =CONCATENATE("VN",E36) -> VN08128
A37: 35 | B37: 20 | C37: KAIFA | D37: =CONCATENATE("#",E37) -> #08232 | E37: 08232 | F37: Phạm Văn Thực | G37: kf.8232 | H37: =CONCATENATE("VN",E37) -> VN08232
A38: 36 | B38: 21 | C38: KAIFA | D38: =CONCATENATE("#",E38) -> #08552 | E38: 08552 | F38: Lê Mạnh Tú | G38: kf.8552 | H38: =CONCATENATE("VN",E38) -> VN08552
A39: 37 | B39: 22 | C39: KAIFA | D39: =CONCATENATE("#",E39) -> #09586 | E39: 09586 | F39: Đỗ Minh Tuấn | G39: kf.9586 | H39: =CONCATENATE("VN",E39) -> VN09586
A40: 38 | B40: 23 | C40: KAIFA | D40: =CONCATENATE("#",E40) -> #09587 | E40: 09587 | F40: Trần Lâm Anh | G40: kf.9587 | H40: =CONCATENATE("VN",E40) -> VN09587
...

Sheet Sheet1
B5: CV cần thực hiện:

Sheet Manage
A1: No. | B1: Dep | C1: USER | D1: 中文姓名 Tên tiếng Trung | E1: 英文 Tên tiếng Anh | F1: ID (vpic1.com) | G1: Password | H1: Create date | I1: Status
A2: 1 | B2: EXEC | C2: DL01 | D2: 詹文龍 | E2: CHAN WEN LONG | F2: =C2 -> DL01 | G2: IT@vpic1
A3: 2 | B3: SON | C3: DL02 | D3: 陳宏鐘 | E3: CHEN HUNG CHUNG | F3: =C3 -> DL02 | G3: IT@vpic1
A4: 3 | B4: ADMI | C4: DL05 | D4: 廖仁成 | E4: LIAO JEN CHENG | F4: =C4 -> DL05 | G4: IT@vpic1
A5: 4 | B5: KAIFA | C5: DL06 | D5: 廖俊興 | E5: LIAO CHUN HSING | F5: =C5 -> DL06 | G5: IT@vpic1
A6: 5 | B6: Ban RD | C6: DL10 | D6: 詹前錦 | E6: CHAN CHIEN CHIN | F6: =C6 -> DL10 | G6: IT@vpic1
A7: 6 | B7: DUC | C7: DL109 | D7: 莊道弦 | E7: CHUANG TAO HSIEN | F7: =C7 -> DL109 | G7: IT@vpic1
A8: 7 | B8: QC | C8: DL110 | D8: 李志迪 | E8: LEE CHIH DI | F8: =C8 -> DL110 | G8: IT@vpic1
A9: 8 | B9: KAIFA | C9: DL111 | D9: 謝啓山 | E9: HSIEH CHI SHAN | F9: =C9 -> DL111 | G9: IT@vpic1
A10: 9 | B10: VP. TGD | C10: DL112 | D10: 蔡協奉 | E10: TSAI HSIEH FENG | F10: =C10 -> DL112 | G10: IT@vpic1
A11: 10 | B11: Ban KTSX | C11: DL122 | D11: 林高偉 | E11: LIN KAO WEI | F11: =C11 -> DL122 | G11: IT@vpic1
A12: 11 | B12: H6 | C12: DL114 | D12: 曾俊達 | E12: TSENG CHUN TA | F12: =C12 -> DL114 | G12: IT@vpic1
A13: 12 | B13: KAIFA | C13: DL120 | D13: 林冠廷 | E13: LIN KUAN TING | F13: =C13 -> DL120 | G13: IT@vpic1
... A31: 38 | B31: VP. TGD | C31: DL115 | D31: 蔡浩然 | E31: TSAI HAO JAN | F31: =C31 -> DL115 | G31: IT@vpic1
A32: 39 | B32: Kinh doanh | C32: DL94 | D32: 林宜慶 | F32: =C32 -> DL94 | G32: IT@vpic1
A33: 40 | B33: Kinh doanh | C33: DL126 | D33: 林子翔 | F33: =C33 -> DL126 | G33: IT@vpic1
A34: 41 | B34: Kaifa X6 | C34: DL125 | D34: 吳仲琪 | E34: WU CHUNG CHI | F34: =C34 -> DL125 | G34: IT@vpic1
